Workbook

Sheet Cover
A1: Valuation Template (Blank)
A3: Ticker
A4: Company name
A5: Valuation date
A6: Reporting currency | B6: USD, millions unless noted
A7: Source — financials
A9: Forward Guidance (latest earnings release)
A10: Period
A11: Revenue, low ($M)
A12: Revenue, high ($M)
A13: Operating income, low ($M)
A14: Operating income, high ($M)
A15: Notes
A17: Forecast vs guidance (sanity)
A18: Y1 forecast revenue | B18: =Forecast!C3
A19: Implied Q-avg ($M, Y1 / 4) | B19: =Forecast!C3/4
A20: Guidance revenue midpoint | B20: =IFERROR((B11+B12)/2,"")
A21: Implied Q-avg / guidance midpoint | B21: =IFERROR(B19/B20,"")
A23: Non-recurring items (carved out for normalization)
A24: #1 Description
A25: #1 Period
A26: #1 Line item
A27: #1 Amount ($M)
A28: #1 Source quote
A29: #2 Description
A30: #2 Period
A31: #2 Line item
A32: #2 Amount ($M)
A33: #2 Source quote
A34: #3 Description
... A40: Other income normalization
A41: Other income (as-reported) | B41: =Historicals!D13
A42: Non-recurring items, sum | B42: =SUM(B27,B32,B37)
A43: Normalized Other income | B43: =B41-B42
A45: Methodology | B45: Two-stage FCFF DCF. Explicit 10-year forecast → terminal value via stable-growth Gordon. Operating leases treated as debt (post-ASC 842).
A47: Cell color legend
A48: Yellow | B48: Analyst input — tunable
A49: Green | B49: Pipeline-populated (sourced from filings/data room)
A50: White | B50: Computed (formula)
A52: Sheets
...

Sheet Inputs
A1: Assumption | B1: Value | C1: Notes
A2: — Capital structure & cost of capital —
A3: Risk-free rate (10Y UST) | B3: 0.042 | C3: Sourced from macro feed; override to lock.
A4: Equity risk premium (mature US) | B4: 0.0475 | C4: Sourced from industry feed (implied ERP); override to lock.
A5: Levered beta | B5: 1.1 | C5: Sourced from industry feed; bottom-up override is appropriate for multi-business issuers.
A6: Pre-tax cost of debt | B6: 0.055 | C6: Sourced from macro feed (BAA corp yield); refine by credit rating.
A7: Marginal tax rate | B7: 0.25 | C7: Statutory + state for jurisdiction of incorporation.
A8: Effective tax rate (current) | C8: Provision / pre-tax income — pipeline pulls from filing.
A10: — Operating story —
A11: Compounded revenue growth, Y1-Y5 | B11: 0.08 | C11: Glide path to terminal. Analyst thesis input.
A12: Target pre-tax operating margin (Y10) | B12: 0.15 | C12: Sourced from industry feed; override for thesis upside/downside.
A13: Year margins reach target | B13: 5 | C13: Linear convergence over this many years.
A14: Sales-to-capital ratio (reinvestment) | B14: 1.5 | C14: Sourced from industry feed when available.
A16: — Terminal-year assumptions —
A17: Terminal growth rate (perpetuity) | B17: 0.042 | C17: Capped at risk-free rate. Analyst input.
A18: Terminal cost of capital | B18: 0.075 | C18: Sourced from industry feed (industry WACC); converges to mature-firm.
A19: Terminal ROIC | B19: 0.12 | C19: Sourced from industry feed; sustainable competitive return.
A21: — Balance sheet add-backs (pipeline-populated) —
A22: Cash & cash equivalents | C22: Most recent balance sheet.
A23: Marketable securities | C23: Most recent balance sheet.
A24: Long-term debt | C24: Most recent balance sheet.
A25: Long-term lease liabilities (treated as debt) | C25: Post-ASC 842; on balance sheet.
A26: Shares outstanding (millions) | C26: Most recent count from cover page.

Sheet Historicals
A1: Line item ($M) | B1: FY-2 | C1: FY-1 | D1: FY (latest)
A2: Net sales
A3: Cost of sales
A4: Fulfillment
A5: Technology and infrastructure
A6: Sales and marketing
A7: General and administrative
A8: Other operating expense
A9: Total operating expenses
A10: Operating income
A11: Interest income
A12: Interest expense
A13: Other income (expense), net
... A16: Net income
A18: Operating margin | B18: =IFERROR(B10/B2,"") | C18: =IFERROR(C10/C2,"") | D18: =IFERROR(D10/D2,"")
A19: Capex (PP&E purchases, net)
A20: Cash from operations
A21: Free cash flow

Sheet Segments
A1: Segment | B1: FY-2 | C1: FY-1 | D1: FY (latest) | E1: YoY growth
A2: Net sales by segment ($M)
E3: =IFERROR(D3/C3-1,"")
E4: =IFERROR(D4/C4-1,"")
E5: =IFERROR(D5/C5-1,"")
E6: =IFERROR(D6/C6-1,"")
E7: =IFERROR(D7/C7-1,"")
A8: Total | B8: =SUM(B3:B7) | C8: =SUM(C3:C7) | D8: =SUM(D3:D7) | E8: =IFERROR(D8/C8-1,"")
A10: Operating income by segment ($M)
A11: =A3
A12: =A4
A13: =A5
A14: =A6
A15: =A7
A16: Total | B16: =SUM(B11:B15) | C16: =SUM(C11:C15) | D16: =SUM(D11:D15)
A18: Operating margin by segment
A19: =A3 | B19: =IFERROR(B11/B3,"") | C19: =IFERROR(C11/C3,"") | D19: =IFERROR(D11/D3,"")
A20: =A4 | B20: =IFERROR(B12/B4,"") | C20: =IFERROR(C12/C4,"") | D20: =IFERROR(D12/D4,"")
A21: =A5 | B21: =IFERROR(B13/B5,"") | C21: =IFERROR(C13/C5,"") | D21: =IFERROR(D13/D5,"")
A22: =A6 | B22: =IFERROR(B14/B6,"") | C22: =IFERROR(C14/C6,"") | D22: =IFERROR(D14/D6,"")
A23: =A7 | B23: =IFERROR(B15/B7,"") | C23: =IFERROR(C15/C7,"") | D23: =IFERROR(D15/D7,"")

Sheet Forecast
A1: Line item ($M) | B1: Base (FY latest) | C1: Y1 | D1: Y2 | E1: Y3 | F1: Y4 | G1: Y5 | H1: Y6 | I1: Y7 | J1: Y8 | K1: Y9 | L1: Y10 | M1: Terminal
A2: Revenue growth rate | C2: =Inputs!B11 | D2: =Inputs!B11 | E2: =Inputs!B11 | F2: =Inputs!B11 | G2: =Inputs!B11 | H2: =Inputs!B11-((Inputs!B11-Inputs!B17)/5)*1 | I2: =Inputs!B11-((Inputs!B11-Inputs!B17)/5)*2 | J2: =Inputs!B11-((Inputs!B11-Inputs!B17)/5)*3 | K2: =Inputs!B11-((Inputs!B11-Inputs!B17)/5)*4 | L2: =Inputs!B11-((Inputs!B11-Inputs!B17)/5)*5 | M2: =Inputs!B17
A3: Revenues | C3: =IFERROR(B3*(1+C2),"") | D3: =IFERROR(C3*(1+D2),"") | E3: =IFERROR(D3*(1+E2),"") | F3: =IFERROR(E3*(1+F2),"") | G3: =IFERROR(F3*(1+G2),"") | H3: =IFERROR(G3*(1+H2),"") | I3: =IFERROR(H3*(1+I2),"") | J3: =IFERROR(I3*(1+J2),"") | ... M3: =IFERROR(L3*(1+M2),"")
A4: Operating margin | C4: =IFERROR(IF(1>Inputs!B13,Inputs!B12,$B$4+((Inputs!B12-$B$4)/Inputs!B13)*1),"") | D4: =IFERROR(IF(2>Inputs!B13,Inputs!B12,$B$4+((Inputs!B12-$B$4)/Inputs!B13)*2),"") | E4: =IFERROR(IF(3>Inputs!B13,Inputs!B12,$B$4+((Inputs!B12-$B$4)/Inputs!B13)*3),"") | F4: =IFERROR(IF(4>Inputs!B13,Inputs!B12,$B$4+((Inputs!B12-$B$4)/Inputs!B13)*4),"") | G4: =IFERROR(IF(5>Inputs!B13,Inputs!B12,$B$4+((Inputs!B12-$B$4)/Inputs!B13)*5),"") | H4: =IFERROR(IF(6>Inputs!B13,Inputs!B12,$B$4+((Inputs!B12-$B$4)/Inputs!B13)*6),"") | I4: =IFERROR(IF(7>Inputs!B13,Inputs!B12,$B$4+((Inputs!B12-$B$4)/Inputs!B13)*7),"") | J4: =IFERROR(IF(8>Inputs!B13,Inputs!B12,$B$4+((Inputs!B12-$B$4)/Inputs!B13)*8),"") | K4: =IFERROR(IF(9>Inputs!B13,Inputs!B12,$B$4+((Inputs!B12-$B$4)/Inputs!B13)*9),"") | L4: =IFERROR(IF(10>Inputs!B13,Inputs!B12,$B$4+((Inputs!B12-$B$4)/Inputs!B13)*10),"") | M4: =Inputs!B12
A5: EBIT | B5: =IFERROR(B3*B4,"") | C5: =IFERROR(C3*C4,"") | D5: =IFERROR(D3*D4,"") | E5: =IFERROR(E3*E4,"") | F5: =IFERROR(F3*F4,"") | G5: =IFERROR(G3*G4,"") | H5: =IFERROR(H3*H4,"") | I5: =IFERROR(I3*I4,"") | ... M5: =IFERROR(M3*M4,"")
A6: Tax rate | B6: =Inputs!B8 | C6: =IFERROR(Inputs!B8+((Inputs!B7-Inputs!B8)/10)*1,"") | D6: =IFERROR(Inputs!B8+((Inputs!B7-Inputs!B8)/10)*2,"") | E6: =IFERROR(Inputs!B8+((Inputs!B7-Inputs!B8)/10)*3,"") | F6: =IFERROR(Inputs!B8+((Inputs!B7-Inputs!B8)/10)*4,"") | G6: =IFERROR(Inputs!B8+((Inputs!B7-Inputs!B8)/10)*5,"") | H6: =IFERROR(Inputs!B8+((Inputs!B7-Inputs!B8)/10)*6,"") | I6: =IFERROR(Inputs!B8+((Inputs!B7-Inputs!B8)/10)*7,"") | J6: =IFERROR(Inputs!B8+((Inputs!B7-Inputs!B8)/10)*8,"") | K6: =IFERROR(Inputs!B8+((Inputs!B7-Inputs!B8)/10)*9,"") | L6: =IFERROR(Inputs!B8+((Inputs!B7-Inputs!B8)/10)*10,"") | M6: =Inputs!B7
A7: EBIT(1-t) | B7: =IFERROR(B5*(1-B6),"") | C7: =IFERROR(C5*(1-C6),"") | D7: =IFERROR(D5*(1-D6),"") | E7: =IFERROR(E5*(1-E6),"") | F7: =IFERROR(F5*(1-F6),"") | G7: =IFERROR(G5*(1-G6),"") | H7: =IFERROR(H5*(1-H6),"") | I7: =IFERROR(I5*(1-I6),"") | ... M7: =IFERROR(M5*(1-M6),"")
A8: Reinvestment (ΔRev / S2C) | C8: =IFERROR((C3-B3)/Inputs!B14,"") | D8: =IFERROR((D3-C3)/Inputs!B14,"") | E8: =IFERROR((E3-D3)/Inputs!B14,"") | F8: =IFERROR((F3-E3)/Inputs!B14,"") | G8: =IFERROR((G3-F3)/Inputs!B14,"") | H8: =IFERROR((H3-G3)/Inputs!B14,"") | I8: =IFERROR((I3-H3)/Inputs!B14,"") | J8: =IFERROR((J3-I3)/Inputs!B14,"") | K8: =IFERROR((K3-J3)/Inputs!B14,"") | L8: =IFERROR((L3-K3)/Inputs!B14,"") | M8: =IFERROR(M7*(Inputs!B17/Inputs!B19),"")
A9: FCFF | C9: =IFERROR(C7-C8,"") | D9: =IFERROR(D7-D8,"") | E9: =IFERROR(E7-E8,"") | F9: =IFERROR(F7-F8,"") | G9: =IFERROR(G7-G8,"") | H9: =IFERROR(H7-H8,"") | I9: =IFERROR(I7-I8,"") | J9: =IFERROR(J7-J8,"") | ... M9: =IFERROR(M7-M8,"")
A10: Cost of capital (WACC) | C10: =WACC!B14 | D10: =WACC!B14 | E10: =WACC!B14 | F10: =WACC!B14 | G10: =WACC!B14 | H10: =WACC!B14-((WACC!B14-Inputs!B18)/5)*1 | I10: =WACC!B14-((WACC!B14-Inputs!B18)/5)*2 | J10: =WACC!B14-((WACC!B14-Inputs!B18)/5)*3 | K10: =WACC!B14-((WACC!B14-Inputs!B18)/5)*4 | L10: =WACC!B14-((WACC!B14-Inputs!B18)/5)*5 | M10: =Inputs!B18
A11: Cumulative discount factor | C11: =1/(1+C10) | D11: =C11*(1/(1+D10)) | E11: =D11*(1/(1+E10)) | F11: =E11*(1/(1+F10)) | G11: =F11*(1/(1+G10)) | H11: =G11*(1/(1+H10)) | I11: =H11*(1/(1+I10)) | J11: =I11*(1/(1+J10)) | K11: =J11*(1/(1+K10)) | L11: =K11*(1/(1+L10))
A12: PV(FCFF) | C12: =IFERROR(C9*C11,"") | D12: =IFERROR(D9*D11,"") | E12: =IFERROR(E9*E11,"") | F12: =IFERROR(F9*F11,"") | G12: =IFERROR(G9*G11,"") | H12: =IFERROR(H9*H11,"") | I12: =IFERROR(I9*I11,"") | J12: =IFERROR(J9*J11,"") | ... L12: =IFERROR(L9*L11,"")

Sheet WACC
A1: WACC build | B1: Value | C1: Notes
A2: Cost of equity
A3: Risk-free rate | B3: =Inputs!B3
A4: Beta | B4: =Inputs!B5
A5: Equity risk premium | B5: =Inputs!B4
A6: Cost of equity = rf + β × ERP | B6: =B3+B4*B5
A8: Cost of debt
A9: Pre-tax cost of debt | B9: =Inputs!B6
A10: Marginal tax rate | B10: =Inputs!B7
A11: After-tax cost of debt | B11: =B9*(1-B10)
A13: Capital structure
A14: WACC | B14: =IF(ISNUMBER(B15),(B15/(B15+(Inputs!B24+Inputs!B25)))*B6 + ((Inputs!B24+Inputs!B25)/(B15+(Inputs!B24+Inputs!B25)))*B11,0.7*B6 + 0.3*B11) | C14: Falls back to 70/30 if market cap blank — flag during validation.
A15: Market cap (override) — for market WACC | C15: Pipeline-populated. If blank, falls back to 70/30 default split.

Sheet Valuation
A1: Valuation output | B1: Value ($M) | C1: Notes
A2: Sum of PV(FCFF), Y1-Y10 | B2: =SUM(Forecast!C12:L12)
A3: Terminal FCFF (Y11) | B3: =Forecast!M9
A4: Terminal value (Gordon) | B4: =IFERROR(B3/(Inputs!B18-Inputs!B17),"")
A5: PV(Terminal value) | B5: =IFERROR(B4*Forecast!L11,"")
A6: Enterprise value (operating) | B6: =B2+B5
A8: Bridge to equity value
A9: (-) Long-term debt | B9: =-Inputs!B24
A10: (-) Long-term lease liabilities | B10: =-Inputs!B25
A11: (+) Cash & equivalents | B11: =Inputs!B22
A12: (+) Marketable securities | B12: =Inputs!B23
A13: Equity value | B13: =B6+B9+B10+B11+B12
A15: Shares outstanding (M) | B15: =Inputs!B26
A16: Implied value per share ($) | B16: =IFERROR(B13/B15,"")
A18: Sanity check vs market
A19: Current market price ($/share)
A20: Implied / Market | B20: =IFERROR(B16/B19,"")
